[2024-08-31 13:09:34,365] 97 werkzeug - INFO - [31m[1mWARNING: This is a development server. Do not use it in a production deployment. Use a production WSGI server instead.[0m
 * Running on all addresses (0.0.0.0)
 * Running on http://127.0.0.1:5000
 * Running on http://192.168.1.4:5000
[2024-08-31 13:09:34,365] 97 werkzeug - INFO - [33mPress CTRL+C to quit[0m
[2024-08-31 13:16:36,178] 18 root - INFO - Exception Error occured in python script name [F:\python\ML_DL_project\MNIST_DIGIT_RECOGNITION\src1\pipeline\predict_pipeline.py] line number [20] error message [tuple index out of range]
[2024-08-31 13:16:36,167] 838 app - ERROR - Exception on /predict_digit_img [GET]
Traceback (most recent call last):
  File "F:\python\ML_DL_project\MNIST_DIGIT_RECOGNITION\src1\pipeline\predict_pipeline.py", line 20, in predict
    data_scaled=preprocessor.transform(features)
  File "F:\python\ML_DL_project\MNIST_DIGIT_RECOGNITION\venv2\lib\site-packages\sklearn\compose\_column_transformer.py", line 556, in transform
    self._check_n_features(X, reset=False)
  File "F:\python\ML_DL_project\MNIST_DIGIT_RECOGNITION\venv2\lib\site-packages\sklearn\base.py", line 352, in _check_n_features
    n_features = X.shape[1]
IndexError: tuple index out of range

During handling of the above exception, another exception occurred:

Traceback (most recent call last):
  File "F:\python\ML_DL_project\MNIST_DIGIT_RECOGNITION\venv2\lib\site-packages\flask\app.py", line 1473, in wsgi_app
    response = self.full_dispatch_request()
  File "F:\python\ML_DL_project\MNIST_DIGIT_RECOGNITION\venv2\lib\site-packages\flask\app.py", line 882, in full_dispatch_request
    rv = self.handle_user_exception(e)
  File "F:\python\ML_DL_project\MNIST_DIGIT_RECOGNITION\venv2\lib\site-packages\flask\app.py", line 880, in full_dispatch_request
    rv = self.dispatch_request()
  File "F:\python\ML_DL_project\MNIST_DIGIT_RECOGNITION\venv2\lib\site-packages\flask\app.py", line 865, in dispatch_request
    return self.ensure_sync(self.view_functions[rule.endpoint])(**view_args)  # type: ignore[no-any-return]
  File "F:\python\ML_DL_project\MNIST_DIGIT_RECOGNITION\app.py", line 26, in predict_img
    results=predict_pipeline.predict(image_reshape)
  File "F:\python\ML_DL_project\MNIST_DIGIT_RECOGNITION\src1\pipeline\predict_pipeline.py", line 25, in predict
    raise CustomException(e,sys)
src1.exception.CustomException: Error occured in python script name [F:\python\ML_DL_project\MNIST_DIGIT_RECOGNITION\src1\pipeline\predict_pipeline.py] line number [20] error message [tuple index out of range]
[2024-08-31 13:16:36,250] 97 werkzeug - INFO - 127.0.0.1 - - [31/Aug/2024 13:16:36] "[35m[1mGET /predict_digit_img HTTP/1.1[0m" 500 -
[2024-08-31 13:19:15,961] 18 root - INFO - Exception Error occured in python script name [F:\python\ML_DL_project\MNIST_DIGIT_RECOGNITION\src1\pipeline\predict_pipeline.py] line number [20] error message [tuple index out of range]
[2024-08-31 13:19:15,961] 838 app - ERROR - Exception on /predict_digit_img [GET]
Traceback (most recent call last):
  File "F:\python\ML_DL_project\MNIST_DIGIT_RECOGNITION\src1\pipeline\predict_pipeline.py", line 20, in predict
    data_scaled=preprocessor.transform(features)
  File "F:\python\ML_DL_project\MNIST_DIGIT_RECOGNITION\venv2\lib\site-packages\sklearn\compose\_column_transformer.py", line 556, in transform
    self._check_n_features(X, reset=False)
  File "F:\python\ML_DL_project\MNIST_DIGIT_RECOGNITION\venv2\lib\site-packages\sklearn\base.py", line 352, in _check_n_features
    n_features = X.shape[1]
IndexError: tuple index out of range

During handling of the above exception, another exception occurred:

Traceback (most recent call last):
  File "F:\python\ML_DL_project\MNIST_DIGIT_RECOGNITION\venv2\lib\site-packages\flask\app.py", line 1473, in wsgi_app
    response = self.full_dispatch_request()
  File "F:\python\ML_DL_project\MNIST_DIGIT_RECOGNITION\venv2\lib\site-packages\flask\app.py", line 882, in full_dispatch_request
    rv = self.handle_user_exception(e)
  File "F:\python\ML_DL_project\MNIST_DIGIT_RECOGNITION\venv2\lib\site-packages\flask\app.py", line 880, in full_dispatch_request
    rv = self.dispatch_request()
  File "F:\python\ML_DL_project\MNIST_DIGIT_RECOGNITION\venv2\lib\site-packages\flask\app.py", line 865, in dispatch_request
    return self.ensure_sync(self.view_functions[rule.endpoint])(**view_args)  # type: ignore[no-any-return]
  File "F:\python\ML_DL_project\MNIST_DIGIT_RECOGNITION\app.py", line 26, in predict_img
    results=predict_pipeline.predict(image_reshape)
  File "F:\python\ML_DL_project\MNIST_DIGIT_RECOGNITION\src1\pipeline\predict_pipeline.py", line 25, in predict
    raise CustomException(e,sys)
src1.exception.CustomException: Error occured in python script name [F:\python\ML_DL_project\MNIST_DIGIT_RECOGNITION\src1\pipeline\predict_pipeline.py] line number [20] error message [tuple index out of range]
[2024-08-31 13:19:15,962] 97 werkzeug - INFO - 127.0.0.1 - - [31/Aug/2024 13:19:15] "[35m[1mGET /predict_digit_img HTTP/1.1[0m" 500 -
[2024-08-31 13:23:42,104] 14 root - INFO - pickle file location -  F:\python\ML_DL_project\MNIST_DIGIT_RECOGNITION\artifact\preprocessor.pkl
[2024-08-31 13:24:13,673] 30 root - INFO - Raw  data is read
[2024-08-31 13:24:27,878] 38 root - INFO - Raw data file captured into artifact directory
[2024-08-31 13:24:27,929] 49 root - INFO - Ingestion main class data captured
[2024-08-31 13:24:37,001] 47 root - INFO - Applying preprocessing object on training dataframe and testing dataframe
[2024-08-31 13:24:59,255] 69 root - INFO - Saved preprocessing object
[2024-08-31 13:26:19,569] 18 root - INFO - Exception Error occured in python script name [F:\python\ML_DL_project\MNIST_DIGIT_RECOGNITION\venv2\lib\site-packages\src1\component\model_trainer.py] line number [40] error message [Exception encountered when calling Sequential.call().

[1mInvalid input shape for input Tensor("data:0", shape=(32,), dtype=float32). Expected shape (None, 784), but input has incompatible shape (32,)[0m

Arguments received by Sequential.call():
  • inputs=tf.Tensor(shape=(32,), dtype=float32)
  • training=False
  • mask=None]
[2024-08-31 13:37:24,487] 14 root - INFO - pickle file location -  F:\python\ML_DL_project\MNIST_DIGIT_RECOGNITION\artifact\preprocessor.pkl
[2024-08-31 13:37:54,640] 30 root - INFO - Raw  data is read
[2024-08-31 13:38:07,360] 38 root - INFO - Raw data file captured into artifact directory
[2024-08-31 13:38:07,410] 49 root - INFO - Ingestion main class data captured
[2024-08-31 13:38:14,172] 47 root - INFO - Applying preprocessing object on training dataframe and testing dataframe
[2024-08-31 13:38:32,137] 69 root - INFO - Saved preprocessing object
[2024-08-31 13:41:03,911] 14 root - INFO - pickle file location -  F:\python\ML_DL_project\MNIST_DIGIT_RECOGNITION\artifact\preprocessor.pkl
[2024-08-31 13:41:32,116] 30 root - INFO - Raw  data is read
[2024-08-31 13:41:44,539] 38 root - INFO - Raw data file captured into artifact directory
[2024-08-31 13:41:44,590] 49 root - INFO - Ingestion main class data captured
[2024-08-31 13:41:51,428] 47 root - INFO - Applying preprocessing object on training dataframe and testing dataframe
[2024-08-31 13:42:09,559] 69 root - INFO - Saved preprocessing object
[2024-08-31 13:43:11,495] 14 root - INFO - pickle file location -  F:\python\ML_DL_project\MNIST_DIGIT_RECOGNITION\artifact\preprocessor.pkl
[2024-08-31 13:43:46,962] 30 root - INFO - Raw  data is read
[2024-08-31 13:43:59,465] 38 root - INFO - Raw data file captured into artifact directory
[2024-08-31 13:43:59,516] 49 root - INFO - Ingestion main class data captured
[2024-08-31 13:44:06,600] 47 root - INFO - Applying preprocessing object on training dataframe and testing dataframe
[2024-08-31 13:44:25,820] 69 root - INFO - Saved preprocessing object
[2024-08-31 13:57:50,939] 14 root - INFO - pickle file location -  F:\python\ML_DL_project\MNIST_DIGIT_RECOGNITION\artifact\preprocessor.pkl
[2024-08-31 13:58:24,052] 30 root - INFO - Raw  data is read
[2024-08-31 13:58:37,773] 38 root - INFO - Raw data file captured into artifact directory
[2024-08-31 13:58:37,821] 49 root - INFO - Ingestion main class data captured
[2024-08-31 13:58:44,978] 47 root - INFO - Applying preprocessing object on training dataframe and testing dataframe
[2024-08-31 13:59:03,451] 69 root - INFO - Saved preprocessing object
[2024-08-31 14:00:19,389] 18 root - INFO - Exception Error occured in python script name [F:\python\ML_DL_project\MNIST_DIGIT_RECOGNITION\venv2\lib\site-packages\src1\component\model_trainer.py] line number [42] error message [Exception encountered when calling Sequential.call().

[1mInvalid input shape for input Tensor("data:0", shape=(32,), dtype=float32). Expected shape (None, 784), but input has incompatible shape (32,)[0m

Arguments received by Sequential.call():
  • inputs=tf.Tensor(shape=(32,), dtype=float32)
  • training=False
  • mask=None]
